Workbook

Sheet Báo cáo công việc
L4: Thống Kê
B5: Tasks | C5: Start date | D5: Due date | E5: Closed date | F5: Estimate (h) | G5: Spent (h) | H5: Số lần bị reopen | I5: Loại task | J5: Tiến độ | L5: Tổng số task
L6: Tổng số task kế hoạch
L7: Tổng số task phát sinh
L8: Tổng thời gian làm việc theo lịch công ty (h) | M8: 192 | N8: Chỗ này luôn để là 192h
L9: Tổng thời gian Estimate (h)
L10: Tổng thời gian Spent time (h)
L11: Tổng thời gian Spent time (h) của task kế hoạch
L12: Tổng thời gian Spent time (h) của task phát sinh
L13: Số lượng task chưa có Start date
L14: Số lượng task chưa có Due date
L15: Số lượng task chưa có Estimate
L16: Số lượng task chưa có Spent time
L17: Tổng số task đúng hạn
L18: Tổng số task trễ hạn
L19: Tổng số task không bị reopen
L20: Tổng số task có bị reopen
L23: Tỉ lệ (%)
L24: Số lượng task chưa có Start date / Tổng số task | M24: =M13/M5*100
L25: Số lượng task chưa có Due date / Tổng số task | M25: =M14/M5*100
L26: Số lượng task chưa có Estimate / Tổng số task | M26: =M15/M5*100
L27: Số lượng task chưa có Spent time / Tổng số task | M27: =M16/M5*100
L28: Tổng số task đúng hạn / Tổng số task | M28: =M17/M5*100
L29: Tổng số task trễ hạn / Tổng số task | M29: =M18/M5*100
L30: Tổng số task không bị reopen / Tổng số task | M30: =M19/M5*100
L31: Tổng số task có bị reopen / Tổng số task | M31: =M20/M5*100
L32: Tổng số task phát sinh / Tổng số task | M32: =M7/M5*100
L33: Tổng thời gian Spent time / Tổng thời gian làm việc theo lịch công ty | M33: =M10/M8*100
L34: Tổng thời gian Spent time / Tổng thời gian Estimate | M34: =M10/M9*100
L35: Tổng thời gian Spent time của task kế hoạch / Tổng thời gian Spent time | M35: =M11/M10*100
L36: Tổng thời gian Spent time của task phát sinh / Tổng thời gian Spent time | M36: =M12/M10*100

Sheet Chấm điểm KPI
A1: BẢNG KPI ĐÁNH GIÁ HIỆU QUẢ CÔNG VIỆC
A3: ="Chu kỳ đánh giá: hàng tháng - "&'Báo cáo công việc'!B2
A4: Cách chấm điểm: Mỗi tiêu chí có điểm tối đa là 5.
A6: Mức điểm KPI | C6: Đánh giá | D6: Chế độ thưởng/phạt hằng tháng
A7: 4,5 - 5 | C7: Xuất sắc | D7: Được xếp loại đánh giá Xuất sắc trong tháng đó.
A8: 4 - 4,49 | C8: Tốt | D8: Được xếp loại đánh giá Tốt trong tháng đó.
A9: 3,5 - 3,99 | C9: Đạt yêu cầu | D9: Không có thưởng phạt.
A10: 2,5 - 3,5 | C10: Kém | D10: Bị cảnh cáo hoặc khiển trách. Có thể xem xét bị chuyển vị trí khác.
A11: < 2,5 | C11: Rất kém | D11: Bị phạt tài chính (5% lương tháng). Có thể xem xét bị chuyển vị trí khác hoặc bị chấm dứt hợp đồng.
A14: No | B14: Tiêu chí | C14: Chỉ số đo lường | D14: Cách đo lường | E14: Trọng số | F14: Số liệu thực tế | G14: Điểm (0-5) | H14: Thang điểm
A15: 1 | B15: Thái độ (Đúng quy trình làm task) | C15: Số lượng task chưa có Estimate / Tổng số task | D15: Dữ liệu từ hệ thống Gitlab | E15: 0.25 | F15: =IF('Báo cáo công việc'!M5=0,"",'Báo cáo công việc'!M26/100) | G15: =IF(F15="","",IF(F15>=0.8,1,IF(F15>=0.5,2,IF(F15>=0.3,3,IF(F15>=0.1,4,5))))) | H15: 1 | I15: ≥ 80%
H16: 2 | I16: 50% - 79%
H17: 3 | I17: 30% - 49%
H18: 4 | I18: 10% - 29%
H19: 5 | I19: < 10%
A20: 2 | C20: Số lượng task chưa có Start date / Tổng số task | D20: Dữ liệu từ hệ thống Gitlab | E20: 0.25 | F20: =IF('Báo cáo công việc'!M5=0,"",'Báo cáo công việc'!M24/100) | G20: =IF(F20="","",IF(F20>=0.8,1,IF(F20>=0.5,2,IF(F20>=0.3,3,IF(F20>=0.1,4,5))))) | H20: 1 | I20: ≥ 80%
H21: 2 | I21: 50% - 79%
H22: 3 | I22: 30% - 49%
H23: 4 | I23: 10% - 29%
H24: 5 | I24: < 10%
A25: 3 | C25: Số lượng task chưa có Due date / Tổng số task | D25: Dữ liệu từ hệ thống Gitlab | E25: 0.25 | F25: =IF('Báo cáo công việc'!M5=0,"",'Báo cáo công việc'!M25/100) | G25: =IF(F25="","",IF(F25>=0.8,1,IF(F25>=0.5,2,IF(F25>=0.3,3,IF(F25>=0.1,4,5))))) | H25: 1 | I25: ≥ 80%
H26: 2 | I26: 50% - 79%
H27: 3 | I27: 30% - 49%
H28: 4 | I28: 10% - 29%
H29: 5 | I29: < 10%
A30: 4 | C30: Số lượng task chưa có Spent time / Tổng số task | D30: Dữ liệu từ hệ thống Gitlab | E30: 0.25 | F30: =IF('Báo cáo công việc'!M5=0,"",'Báo cáo công việc'!M27/100) | G30: =IF(F30="","",IF(F30>=0.8,1,IF(F30>=0.5,2,IF(F30>=0.3,3,IF(F30>=0.1,4,5))))) | H30: 1 | I30: ≥ 80%
H31: 2 | I31: 50% - 79%
H32: 3 | I32: 30% - 49%
H33: 4 | I33: 10% - 29%
H34: 5 | I34: < 10%
A35: 5 | B35: Khối lượng | C35: Tổng thời gian Spent time / Tổng thời gian làm việc theo lịch công ty | D35: Dữ liệu từ hệ thống Gitlab | E35: 3 | F35: =IF('Báo cáo công việc'!M5=0,"",'Báo cáo công việc'!M33) | G35: =IF(F35="","",IF(F35>=100,5,IF(F35>=90,4,IF(F35>=80,3,IF(F35>=70,2,1))))) | H35: 1 | I35: < 70%
H36: 2 | I36: 70% - 79%
H37: 3 | I37: 80% - 89%
H38: 4 | I38: 90% - 99%
H39: 5 | I39: ≥ 100%
A40: 6 | B40: Chất lượng | C40: Tổng số task trễ hạn / Tổng số task | D40: Dữ liệu từ hệ thống Gitlab | E40: 3 | F40: =IF('Báo cáo công việc'!M5=0,"",'Báo cáo công việc'!M29/100) | G40: =IF(F40="","",IF(F40>=0.8,1,IF(F40>=0.5,2,IF(F40>=0.3,3,IF(F40>=0.1,4,5))))) | H40: 1 | I40: ≥ 80%
H41: 2 | I41: 50% - 79%
H42: 3 | I42: 30% - 49%
H43: 4 | I43: 10% - 29%
H44: 5 | I44: < 10%
...
